2025-07-24 04:46:06,925 - INFO - Model loaded from C:\Users\dhana\OneDrive\Desktop\AI - 2nd year\Sem 2\Enterprise system\Lab3\lab3_Dhanachitra_Dhanapal\app\data\model.json
2025-07-24 04:49:44,067 - INFO - Model loaded from C:\Users\dhana\OneDrive\Desktop\AI - 2nd year\Sem 2\Enterprise system\Lab3\lab3_Dhanachitra_Dhanapal\app\data\model.json
2025-07-24 04:50:23,670 - INFO - Received request: bill_length_mm=0.0 bill_depth_mm=0.0 flipper_length_mm=0.0 body_mass_g=0.0 year=0 sex=<Sex.Male: 'male'> island=<Island.Torgersen: 'Torgersen'>
2025-07-24 04:50:23,693 - ERROR - Prediction error: feature_names mismatch: ['bill_length_mm', 'bill_depth_mm', 'flipper_length_mm', 'body_mass_g', 'sex_Female', 'sex_Male', 'island_Biscoe', 'island_Dream', 'island_Torgersen'] ['bill_length_mm', 'bill_depth_mm', 'flipper_length_mm', 'body_mass_g', 'year', 'sex_Female', 'sex_Male', 'island_Biscoe', 'island_Dream', 'island_Torgersen']
training data did not have the following fields: year
Traceback (most recent call last):
  File "C:\Users\dhana\OneDrive\Desktop\AI - 2nd year\Sem 2\Enterprise system\Lab3\lab3_Dhanachitra_Dhanapal\app\main.py", line 95, in predict
    prediction = model.predict(X_input)[0]
                 ^^^^^^^^^^^^^^^^^^^^^^
  File "C:\Users\dhana\OneDrive\Desktop\AI - 2nd year\Sem 2\Enterprise system\Lab3\lab3_Dhanachitra_Dhanapal\.venv\Lib\site-packages\xgboost\core.py", line 729, in inner_f
    return func(**kwargs)
           ^^^^^^^^^^^^^^
  File "C:\Users\dhana\OneDrive\Desktop\AI - 2nd year\Sem 2\Enterprise system\Lab3\lab3_Dhanachitra_Dhanapal\.venv\Lib\site-packages\xgboost\sklearn.py", line 1718, in predict
    class_probs = super().predict(
                  ^^^^^^^^^^^^^^^^
  File "C:\Users\dhana\OneDrive\Desktop\AI - 2nd year\Sem 2\Enterprise system\Lab3\lab3_Dhanachitra_Dhanapal\.venv\Lib\site-packages\xgboost\core.py", line 729, in inner_f
    return func(**kwargs)
           ^^^^^^^^^^^^^^
  File "C:\Users\dhana\OneDrive\Desktop\AI - 2nd year\Sem 2\Enterprise system\Lab3\lab3_Dhanachitra_Dhanapal\.venv\Lib\site-packages\xgboost\sklearn.py", line 1327, in predict
    predts = self.get_booster().inplace_predict(
             ^^^^^^^^^^^^^^^^^^^^^^^^^^^^^^^^^^^
  File "C:\Users\dhana\OneDrive\Desktop\AI - 2nd year\Sem 2\Enterprise system\Lab3\lab3_Dhanachitra_Dhanapal\.venv\Lib\site-packages\xgboost\core.py", line 729, in inner_f
    return func(**kwargs)
           ^^^^^^^^^^^^^^
  File "C:\Users\dhana\OneDrive\Desktop\AI - 2nd year\Sem 2\Enterprise system\Lab3\lab3_Dhanachitra_Dhanapal\.venv\Lib\site-packages\xgboost\core.py", line 2667, in inplace_predict
    self._validate_features(fns)
  File "C:\Users\dhana\OneDrive\Desktop\AI - 2nd year\Sem 2\Enterprise system\Lab3\lab3_Dhanachitra_Dhanapal\.venv\Lib\site-packages\xgboost\core.py", line 3243, in _validate_features
    raise ValueError(msg.format(self.feature_names, feature_names))
ValueError: feature_names mismatch: ['bill_length_mm', 'bill_depth_mm', 'flipper_length_mm', 'body_mass_g', 'sex_Female', 'sex_Male', 'island_Biscoe', 'island_Dream', 'island_Torgersen'] ['bill_length_mm', 'bill_depth_mm', 'flipper_length_mm', 'body_mass_g', 'year', 'sex_Female', 'sex_Male', 'island_Biscoe', 'island_Dream', 'island_Torgersen']
training data did not have the following fields: year
